Workbook
Name Slicer_PRODUCTLINE: #N/A
Name Slicer_YEAR_ID: #N/A

Sheet sales_data_sample (1)
A1: ORDERNUMBER | B1: QUANTITYORDERED | C1: PRICEEACH | D1: ORDERLINENUMBER | E1: SALES | F1: ORDERDATE | G1: STATUS | H1: QTR_ID | I1: MONTH_ID | J1: YEAR_ID | K1: PRODUCTLINE | L1: MSRP | M1: PRODUCTCODE | N1: CUSTOMERNAME | O1: PHONE | P1: ADDRESSLINE1 | Q1: ADDRESSLINE2 | R1: CITY | S1: STATE | T1: POSTALCODE | U1: COUNTRY | V1: TERRITORY | W1: CONTACTLASTNAME | X1: CONTACTFIRSTNAME | Y1: DEALSIZE
A2: 10107 | B2: 30 | C2: 95.7 | D2: 2 | E2: 2871 | F2: 2/24/2003 0:00 | G2: Shipped | H2: 1 | I2: 2 | J2: 2003 | K2: Motorcycles | L2: 95 | M2: S10_1678 | N2: Land of Toys Inc. | O2: 2125557818 | P2: 897 Long Airport Avenue | R2: NYC | S2: NY | T2: 10022 | U2: USA | V2: NA | W2: Yu | X2: Kwai | Y2: Small
A3: 10121 | B3: 34 | C3: 81.35 | D3: 5 | E3: 2765.9 | F3: 37807 | G3: Shipped | H3: 2 | I3: 5 | J3: 2003 | K3: Motorcycles | L3: 95 | M3: S10_1678 | N3: Reims Collectables | O3: 26.47.1555 | P3: 59 rue de l'Abbaye | R3: Reims | T3: 51100 | U3: France | V3: EMEA | W3: Henriot | X3: Paul | Y3: Small
A4: 10134 | B4: 41 | C4: 94.74 | D4: 2 | E4: 3884.34 | F4: 37628 | G4: Shipped | H4: 3 | I4: 7 | J4: 2003 | K4: Motorcycles | L4: 95 | M4: S10_1678 | N4: Lyon Souveniers | O4: +33 1 46 62 7555 | P4: 27 rue du Colonel Pierre Avia | R4: Paris | T4: 75508 | U4: France | V4: EMEA | W4: Da Cunha | X4: Daniel | Y4: Medium
A5: 10145 | B5: 45 | C5: 83.26 | D5: 6 | E5: 3746.7 | F5: 8/25/2003 0:00 | G5: Shipped | H5: 3 | I5: 8 | J5: 2003 | K5: Motorcycles | L5: 95 | M5: S10_1678 | N5: Toys4GrownUps.com | O5: 6265557265 | P5: 78934 Hillside Dr. | R5: Pasadena | S5: CA | T5: 90003 | U5: USA | V5: NA | W5: Young | X5: Julie | Y5: Medium
A6: 10159 | B6: 49 | C6: 100 | D6: 14 | E6: 5205.27 | F6: 37904 | G6: Shipped | H6: 4 | I6: 10 | J6: 2003 | K6: Motorcycles | L6: 95 | M6: S10_1678 | N6: Corporate Gift Ideas Co. | O6: 6505551386 | P6: 7734 Strong St. | R6: San Francisco | S6: CA | U6: USA | V6: NA | W6: Brown | X6: Julie | Y6: Medium
A7: 10168 | B7: 36 | C7: 96.66 | D7: 1 | E7: 3479.76 | F7: 10/28/2003 0:00 | G7: Shipped | H7: 4 | I7: 10 | J7: 2003 | K7: Motorcycles | L7: 95 | M7: S10_1678 | N7: Technics Stores Inc. | O7: 6505556809 | P7: 9408 Furth Circle | R7: Burlingame | S7: CA | T7: 94217 | U7: USA | V7: NA | W7: Hirano | X7: Juri | Y7: Medium
A8: 10180 | B8: 29 | C8: 86.13 | D8: 9 | E8: 2497.77 | F8: 37936 | G8: Shipped | H8: 4 | I8: 11 | J8: 2003 | K8: Motorcycles | L8: 95 | M8: S10_1678 | N8: Daedalus Designs Imports | O8: 20.16.1555 | P8: 184, chausse de Tournai | R8: Lille | T8: 59000 | U8: France | V8: EMEA | W8: Rance | X8: Martine | Y8: Small
A9: 10188 | B9: 48 | C9: 100 | D9: 1 | E9: 5512.32 | F9: 11/18/2003 0:00 | G9: Shipped | H9: 4 | I9: 11 | J9: 2003 | K9: Motorcycles | L9: 95 | M9: S10_1678 | N9: Herkku Gifts | O9: +47 2267 3215 | P9: Drammen 121, PR 744 Sentrum | R9: Bergen | T9: N 5804 | U9: Norway | V9: EMEA | W9: Oeztan | X9: Veysel | Y9: Medium
A10: 10201 | B10: 22 | C10: 98.57 | D10: 2 | E10: 2168.54 | F10: 37633 | G10: Shipped | H10: 4 | I10: 12 | J10: 2003 | K10: Motorcycles | L10: 95 | M10: S10_1678 | N10: Mini Wheels Co. | O10: 6505555787 | P10: 5557 North Pendale Street | R10: San Francisco | S10: CA | U10: USA | V10: NA | W10: Murphy | X10: Julie | Y10: Small
A11: 10211 | B11: 41 | C11: 100 | D11: 14 | E11: 4708.44 | F11: 1/15/2004 0:00 | G11: Shipped | H11: 1 | I11: 1 | J11: 2004 | K11: Motorcycles | L11: 95 | M11: S10_1678 | N11: Auto Canal Petit | O11: (1) 47.55.6555 | P11: 25, rue Lauriston | R11: Paris | T11: 75016 | U11: France | V11: EMEA | W11: Perrier | X11: Dominique | Y11: Medium
A12: 10223 | B12: 37 | C12: 100 | D12: 1 | E12: 3965.66 | F12: 2/20/2004 0:00 | G12: Shipped | H12: 1 | I12: 2 | J12: 2004 | K12: Motorcycles | L12: 95 | M12: S10_1678 | N12: Australian Collectors, Co. | O12: 03 9520 4555 | P12: 636 St Kilda Road | Q12: Level 3 | R12: Melbourne | S12: Victoria | T12: 3004 | U12: Australia | V12: APAC | W12: Ferguson | X12: Peter | Y12: Medium
A13: 10237 | B13: 23 | C13: 100 | D13: 7 | E13: 2333.12 | F13: 38111 | G13: Shipped | H13: 2 | I13: 4 | J13: 2004 | K13: Motorcycles | L13: 95 | M13: S10_1678 | N13: Vitachrome Inc. | O13: 2125551500 | P13: 2678 Kingston Rd. | Q13: Suite 101 | R13: NYC | S13: NY | T13: 10022 | U13: USA | V13: NA | W13: Frick | X13: Michael | Y13: Small
A14: 10251 | B14: 28 | C14: 100 | D14: 2 | E14: 3188.64 | F14: 5/18/2004 0:00 | G14: Shipped | H14: 2 | I14: 5 | J14: 2004 | K14: Motorcycles | L14: 95 | M14: S10_1678 | N14: Tekni Collectables Inc. | O14: 2015559350 | P14: 7476 Moss Rd. | R14: Newark | S14: NJ | T14: 94019 | U14: USA | V14: NA | W14: Brown | X14: William | Y14: Medium
A15: 10263 | B15: 34 | C15: 100 | D15: 2 | E15: 3676.76 | F15: 6/28/2004 0:00 | G15: Shipped | H15: 2 | I15: 6 | J15: 2004 | K15: Motorcycles | L15: 95 | M15: S10_1678 | N15: Gift Depot Inc. | O15: 2035552570 | P15: 25593 South Bay Ln. | R15: Bridgewater | S15: CT | T15: 97562 | U15: USA | V15: NA | W15: King | X15: Julie | Y15: Medium
A16: 10275 | B16: 45 | C16: 92.83 | D16: 1 | E16: 4177.35 | F16: 7/23/2004 0:00 | G16: Shipped | H16: 3 | I16: 7 | J16: 2004 | K16: Motorcycles | L16: 95 | M16: S10_1678 | N16: La Rochelle Gifts | O16: 40.67.8555 | P16: 67, rue des Cinquante Otages | R16: Nantes | T16: 44000 | U16: France | V16: EMEA | W16: Labrune | X16: Janine | Y16: Medium
A17: 10285 | B17: 36 | C17: 100 | D17: 6 | E17: 4099.68 | F17: 8/27/2004 0:00 | G17: Shipped | H17: 3 | I17: 8 | J17: 2004 | K17: Motorcycles | L17: 95 | M17: S10_1678 | N17: Marta's Replicas Co. | O17: 6175558555 | P17: 39323 Spinnaker Dr. | R17: Cambridge | S17: MA | T17: 51247 | U17: USA | V17: NA | W17: Hernandez | X17: Marta | Y17: Medium
A18: 10299 | B18: 23 | C18: 100 | D18: 9 | E18: 2597.39 | F18: 9/30/2004 0:00 | G18: Shipped | H18: 3 | I18: 9 | J18: 2004 | K18: Motorcycles | L18: 95 | M18: S10_1678 | N18: Toys of Finland, Co. | O18: 90-224 8555 | P18: Keskuskatu 45 | R18: Helsinki | T18: 21240 | U18: Finland | V18: EMEA | W18: Karttunen | X18: Matti | Y18: Small
A19: 10309 | B19: 41 | C19: 100 | D19: 5 | E19: 4394.38 | F19: 10/15/2004 0:00 | G19: Shipped | H19: 4 | I19: 10 | J19: 2004 | K19: Motorcycles | L19: 95 | M19: S10_1678 | N19: Baane Mini Imports | O19: 07-98 9555 | P19: Erling Skakkes gate 78 | R19: Stavern | T19: 4110 | U19: Norway | V19: EMEA | W19: Bergulfsen | X19: Jonas | Y19: Medium
A20: 10318 | B20: 46 | C20: 94.74 | D20: 1 | E20: 4358.04 | F20: 38028 | G20: Shipped | H20: 4 | I20: 11 | J20: 2004 | K20: Motorcycles | L20: 95 | M20: S10_1678 | N20: Diecast Classics Inc. | O20: 2155551555 | P20: 7586 Pompton St. | R20: Allentown | S20: PA | T20: 70267 | U20: USA | V20: NA | W20: Yu | X20: Kyung | Y20: Medium
A21: 10329 | B21: 42 | C21: 100 | D21: 1 | E21: 4396.14 | F21: 11/15/2004 0:00 | G21: Shipped | H21: 4 | I21: 11 | J21: 2004 | K21: Motorcycles | L21: 95 | M21: S10_1678 | N21: Land of Toys Inc. | O21: 2125557818 | P21: 897 Long Airport Avenue | R21: NYC | S21: NY | T21: 10022 | U21: USA | V21: NA | W21: Yu | X21: Kwai | Y21: Medium
A22: 10341 | B22: 41 | C22: 100 | D22: 9 | E22: 7737.93 | F22: 11/24/2004 0:00 | G22: Shipped | H22: 4 | I22: 11 | J22: 2004 | K22: Motorcycles | L22: 95 | M22: S10_1678 | N22: Salzburg Collectables | O22: 6562-9555 | P22: Geislweg 14 | R22: Salzburg | T22: 5020 | U22: Austria | V22: EMEA | W22: Pipps | X22: Georg | Y22: Large
A23: 10361 | B23: 20 | C23: 72.55 | D23: 13 | E23: 1451 | F23: 12/17/2004 0:00 | G23: Shipped | H23: 4 | I23: 12 | J23: 2004 | K23: Motorcycles | L23: 95 | M23: S10_1678 | N23: Souveniers And Things Co. | O23: +61 2 9495 8555 | P23: Monitor Money Building, 815 Pacific Hwy | Q23: Level 6 | R23: Chatswood | S23: NSW | T23: 2067 | U23: Australia | V23: APAC | W23: Huxley | X23: Adrian | Y23: Small
A24: 10375 | B24: 21 | C24: 34.91 | D24: 12 | E24: 733.11 | F24: 38413 | G24: Shipped | H24: 1 | I24: 2 | J24: 2005 | K24: Motorcycles | L24: 95 | M24: S10_1678 | N24: La Rochelle Gifts | O24: 40.67.8555 | P24: 67, rue des Cinquante Otages | R24: Nantes | T24: 44000 | U24: France | V24: EMEA | W24: Labrune | X24: Janine | Y24: Small
A25: 10388 | B25: 42 | C25: 76.36 | D25: 4 | E25: 3207.12 | F25: 38414 | G25: Shipped | H25: 1 | I25: 3 | J25: 2005 | K25: Motorcycles | L25: 95 | M25: S10_1678 | N25: FunGiftIdeas.com | O25: 5085552555 | P25: 1785 First Street | R25: New Bedford | S25: MA | T25: 50553 | U25: USA | V25: NA | W25: Benitez | X25: Violeta | Y25: Medium
A26: 10403 | B26: 24 | C26: 100 | D26: 7 | E26: 2434.56 | F26: 38568 | G26: Shipped | H26: 2 | I26: 4 | J26: 2005 | K26: Motorcycles | L26: 95 | M26: S10_1678 | N26: UK Collectables, Ltd. | O26: (171) 555-2282 | P26: Berkeley Gardens 12 Brewery | R26: Liverpool | T26: WX1 6LT | U26: UK | V26: EMEA | W26: Devon | X26: Elizabeth | Y26: Small
A27: 10417 | B27: 66 | C27: 100 | D27: 2 | E27: 7516.08 | F27: 5/13/2005 0:00 | G27: Disputed | H27: 2 | I27: 5 | J27: 2005 | K27: Motorcycles | L27: 95 | M27: S10_1678 | N27: Euro Shopping Channel | O27: (91) 555 94 44 | P27: C/ Moralzarzal, 86 | R27: Madrid | T27: 28034 | U27: Spain | V27: EMEA | W27: Freyre | X27: Diego | Y27: Large
A28: 10103 | B28: 26 | C28: 100 | D28: 11 | E28: 5404.62 | F28: 1/29/2003 0:00 | G28: Shipped | H28: 1 | I28: 1 | J28: 2003 | K28: Classic Cars | L28: 214 | M28: S10_1949 | N28: Baane Mini Imports | O28: 07-98 9555 | P28: Erling Skakkes gate 78 | R28: Stavern | T28: 4110 | U28: Norway | V28: EMEA | W28: Bergulfsen | X28: Jonas | Y28: Medium
A29: 10112 | B29: 29 | C29: 100 | D29: 1 | E29: 7209.11 | F29: 3/24/2003 0:00 | G29: Shipped | H29: 1 | I29: 3 | J29: 2003 | K29: Classic Cars | L29: 214 | M29: S10_1949 | N29: Volvo Model Replicas, Co | O29: 0921-12 3555 | P29: Berguvsv„gen 8 | R29: Lule | T29: S-958 22 | U29: Sweden | V29: EMEA | W29: Berglund | X29: Christina | Y29: Large
A30: 10126 | B30: 38 | C30: 100 | D30: 11 | E30: 7329.06 | F30: 5/28/2003 0:00 | G30: Shipped | H30: 2 | I30: 5 | J30: 2003 | K30: Classic Cars | L30: 214 | M30: S10_1949 | N30: Corrida Auto Replicas, Ltd | O30: (91) 555 22 82 | P30: C/ Araquil, 67 | R30: Madrid | T30: 28023 | U30: Spain | V30: EMEA | W30: Sommer | X30: Mart¡n | Y30: Large
A31: 10140 | B31: 37 | C31: 100 | D31: 11 | E31: 7374.1 | F31: 7/24/2003 0:00 | G31: Shipped | H31: 3 | I31: 7 | J31: 2003 | K31: Classic Cars | L31: 214 | M31: S10_1949 | N31: Technics Stores Inc. | O31: 6505556809 | P31: 9408 Furth Circle | R31: Burlingame | S31: CA | T31: 94217 | U31: USA | V31: NA | W31: Hirano | X31: Juri | Y31: Large
A32: 10150 | B32: 45 | C32: 100 | D32: 8 | E32: 10993.5 | F32: 9/19/2003 0:00 | G32: Shipped | H32: 3 | I32: 9 | J32: 2003 | K32: Classic Cars | L32: 214 | M32: S10_1949 | N32: Dragon Souveniers, Ltd. | O32: +65 221 7555 | P32: Bronz Sok., Bronz Apt. 3/6 Tesvikiye | R32: Singapore | T32: 79903 | U32: Singapore | V32: Japan | W32: Natividad | X32: Eric | Y32: Large
A33: 10163 | B33: 21 | C33: 100 | D33: 1 | E33: 4860.24 | F33: 10/20/2003 0:00 | G33: Shipped | H33: 4 | I33: 10 | J33: 2003 | K33: Classic Cars | L33: 214 | M33: S10_1949 | N33: Classic Legends Inc. | O33: 2125558493 | P33: 5905 Pompton St. | Q33: Suite 750 | R33: NYC | S33: NY | T33: 10022 | U33: USA | V33: NA | W33: Hernandez | X33: Maria | Y33: Medium
A34: 10174 | B34: 34 | C34: 100 | D34: 4 | E34: 8014.82 | F34: 37783 | G34: Shipped | H34: 4 | I34: 11 | J34: 2003 | K34: Classic Cars | L34: 214 | M34: S10_1949 | N34: Australian Gift Network, Co | O34: 61-7-3844-6555 | P34: 31 Duncan St. West End | R34: South Brisbane | S34: Queensland | T34: 4101 | U34: Australia | V34: APAC | W34: Calaghan | X34: Tony | Y34: Large
A35: 10183 | B35: 23 | C35: 100 | D35: 8 | E35: 5372.57 | F35: 11/13/2003 0:00 | G35: Shipped | H35: 4 | I35: 11 | J35: 2003 | K35: Classic Cars | L35: 214 | M35: S10_1949 | N35: Classic Gift Ideas, Inc | O35: 2155554695 | P35: 782 First Street | R35: Philadelphia | S35: PA | T35: 71270 | U35: USA | V35: NA | W35: Cervantes | X35: Francisca | Y35: Medium
A36: 10194 | B36: 42 | C36: 100 | D36: 11 | E36: 7290.36 | F36: 11/25/2003 0:00 | G36: Shipped | H36: 4 | I36: 11 | J36: 2003 | K36: Classic Cars | L36: 214 | M36: S10_1949 | N36: Saveley & Henriot, Co. | O36: 78.32.5555 | P36: 2, rue du Commerce | R36: Lyon | T36: 69004 | U36: France | V36: EMEA | W36: Saveley | X36: Mary | Y36: Large
A37: 10206 | B37: 47 | C37: 100 | D37: 6 | E37: 9064.89 | F37: 37753 | G37: Shipped | H37: 4 | I37: 12 | J37: 2003 | K37: Classic Cars | L37: 214 | M37: S10_1949 | N37: Canadian Gift Exchange Network | O37: (604) 555-3392 | P37: 1900 Oak St. | R37: Vancouver | S37: BC | T37: V3F 2K1 | U37: Canada | V37: NA | W37: Tannamuri | X37: Yoshi | Y37: Large
A38: 10215 | B38: 35 | C38: 100 | D38: 3 | E38: 6075.3 | F38: 1/29/2004 0:00 | G38: Shipped | H38: 1 | I38: 1 | J38: 2004 | K38: Classic Cars | L38: 214 | M38: S10_1949 | N38: West Coast Collectables Co. | O38: 3105553722 | P38: 3675 Furth Circle | R38: Burbank | S38: CA | T38: 94019 | U38: USA | V38: NA | W38: Thompson | X38: Steve | Y38: Medium
A39: 10228 | B39: 29 | C39: 100 | D39: 2 | E39: 6463.23 | F39: 38263 | G39: Shipped | H39: 1 | I39: 3 | J39: 2004 | K39: Classic Cars | L39: 214 | M39: S10_1949 | N39: Cambridge Collectables Co. | O39: 6175555555 | P39: 4658 Baden Av. | R39: Cambridge | S39: MA | T39: 51247 | U39: USA | V39: NA | W39: Tseng | X39: Kyung | Y39: Medium
A40: 10245 | B40: 34 | C40: 100 | D40: 9 | E40: 6120.34 | F40: 38082 | G40: Shipped | H40: 2 | I40: 5 | J40: 2004 | K40: Classic Cars | L40: 214 | M40: S10_1949 | N40: Super Scale Inc. | O40: 2035559545 | P40: 567 North Pendale Street | R40: New Haven | S40: CT | T40: 97823 | U40: USA | V40: NA | W40: Murphy | X40: Leslie | Y40: Medium
...

Sheet sales_data_sample (2)
A1: ORDERNUMBER | B1: QUANTITYORDERED | C1: PRICEEACH | D1: ORDERLINENUMBER | E1: SALES | F1: ORDERDATE | G1: Month | H1: STATUS | I1: QTR_ID | J1: MONTH_ID | K1: YEAR_ID | L1: PRODUCTLINE | M1: MSRP | N1: PRODUCTCODE | O1: CUSTOMERNAME | P1: PHONE | Q1: ADDRESSLINE1 | R1: ADDRESSLINE2 | S1: CITY | T1: STATE | U1: POSTALCODE | V1: COUNTRY | W1: TERRITORY | X1: CONTACTLASTNAME | Y1: CONTACTFIRSTNAME | Z1: DEALSIZE
A2: 10100 | B2: 30 | C2: 100 | D2: 3 | E2: 5151 | F2: 37627 | G2: =TEXT(F2,"MMM") -> Jan | H2: Shipped | I2: 1 | J2: 1 | K2: 2003 | L2: Vintage Cars | M2: 170 | N2: S18_1749 | O2: Online Diecast Creations Co. | P2: 6035558647 | Q2: 2304 Long Airport Avenue | R2: N/A | S2: Nashua | T2: NH | U2: 62005 | V2: USA | W2: NA | X2: Young | Y2: Valarie | Z2: Medium
A3: 10101 | B3: 25 | C3: 100 | D3: 4 | E3: 3782 | F3: 37630 | G3: =TEXT(F3,"MMM") -> Jan | H3: Shipped | I3: 1 | J3: 1 | K3: 2003 | L3: Vintage Cars | M3: 127 | N3: S18_2325 | O3: Blauer See Auto, Co. | P3: +49 69 66 90 2555 | Q3: Lyonerstr. 34 | R3: N/A | S3: Frankfurt | T3: N/A | U3: 60528 | V3: Germany | W3: EMEA | X3: Keitel | Y3: Roland | Z3: Medium
A4: 10102 | B4: 39 | C4: 100 | D4: 2 | E4: 4808.31 | F4: 37631 | G4: =TEXT(F4,"MMM") -> Jan | H4: Shipped | I4: 1 | J4: 1 | K4: 2003 | L4: Vintage Cars | M4: 102 | N4: S18_1342 | O4: Vitachrome Inc. | P4: 2125551500 | Q4: 2678 Kingston Rd. | R4: Suite 101 | S4: NYC | T4: NY | U4: 10022 | V4: USA | W4: NA | X4: Frick | Y4: Michael | Z4: Medium
A5: 10103 | B5: 26 | C5: 100 | D5: 11 | E5: 5404.62 | F5: 37650 | G5: =TEXT(F5,"MMM") -> Jan | H5: Shipped | I5: 1 | J5: 1 | K5: 2003 | L5: Classic Cars | M5: 214 | N5: S10_1949 | O5: Baane Mini Imports | P5: 07-98 9555 | Q5: Erling Skakkes gate 78 | R5: N/A | S5: Stavern | T5: N/A | U5: 4110 | V5: Norway | W5: EMEA | X5: Bergulfsen | Y5: Jonas | Z5: Medium
A6: 10104 | B6: 34 | C6: 100 | D6: 1 | E6: 5958.5 | F6: 37652 | G6: =TEXT(F6,"MMM") -> Jan | H6: Shipped | I6: 1 | J6: 1 | K6: 2003 | L6: Classic Cars | M6: 151 | N6: S12_3148 | O6: Euro Shopping Channel | P6: (91) 555 94 44 | Q6: C/ Moralzarzal, 86 | R6: N/A | S6: Madrid | T6: N/A | U6: 28034 | V6: Spain | W6: EMEA | X6: Freyre | Y6: Diego | Z6: Medium
A7: 10105 | B7: 50 | C7: 100 | D7: 2 | E7: 7208 | F7: 37663 | G7: =TEXT(F7,"MMM") -> Feb | H7: Shipped | I7: 1 | J7: 2 | K7: 2003 | L7: Classic Cars | M7: 136 | N7: S10_4757 | O7: Danish Wholesale Imports | P7: 31 12 3555 | Q7: Vinb'ltet 34 | R7: N/A | S7: Kobenhavn | T7: N/A | U7: 1734 | V7: Denmark | W7: EMEA | X7: Petersen | Y7: Jytte | Z7: Large
A8: 10106 | B8: 36 | C8: 100 | D8: 12 | E8: 5279.4 | F8: 37669 | G8: =TEXT(F8,"MMM") -> Feb | H8: Shipped | I8: 1 | J8: 2 | K8: 2003 | L8: Planes | M8: 157 | N8: S18_1662 | O8: Rovelli Gifts | P8: 035-640555 | Q8: Via Ludovico il Moro 22 | R8: N/A | S8: Bergamo | T8: N/A | U8: 24100 | V8: Italy | W8: EMEA | X8: Rovelli | Y8: Giovanni | Z8: Medium
A9: 10107 | B9: 30 | C9: 95.7 | D9: 2 | E9: 2871 | F9: 37676 | G9: =TEXT(F9,"MMM") -> Feb | H9: Shipped | I9: 1 | J9: 2 | K9: 2003 | L9: Motorcycles | M9: 95 | N9: S10_1678 | O9: Land of Toys Inc. | P9: 2125557818 | Q9: 897 Long Airport Avenue | R9: N/A | S9: NYC | T9: NY | U9: 10022 | V9: USA | W9: NA | X9: Yu | Y9: Kwai | Z9: Small
A10: 10108 | B10: 33 | C10: 100 | D10: 6 | E10: 5265.15 | F10: 37683 | G10: =TEXT(F10,"MMM") -> Mar | H10: Shipped | I10: 1 | J10: 3 | K10: 2003 | L10: Classic Cars | M10: 194 | N10: S12_1099 | O10: Cruz & Sons Co. | P10: +63 2 555 3587 | Q10: 15 McCallum Street - NatWest Center #13-03 | R10: N/A | S10: Makati City | T10: N/A | U10: 1227 MM | V10: Philippines | W10: Japan | X10: Cruz | Y10: Arnold | Z10: Medium
A11: 10109 | B11: 26 | C11: 100 | D11: 4 | E11: 4379.18 | F11: 37690 | G11: =TEXT(F11,"MMM") -> Mar | H11: Shipped | I11: 1 | J11: 3 | K11: 2003 | L11: Classic Cars | M11: 141 | N11: S18_1129 | O11: Motor Mint Distributors Inc. | P11: 2155559857 | Q11: 11328 Douglas Av. | R11: N/A | S11: Philadelphia | T11: PA | U11: 71270 | V11: USA | W11: NA | X11: Hernandez | Y11: Rosa | Z11: Medium
A12: 10110 | B12: 37 | C12: 100 | D12: 16 | E12: 5433.08 | F12: 37698 | G12: =TEXT(F12,"MMM") -> Mar | H12: Shipped | I12: 1 | J12: 3 | K12: 2003 | L12: Classic Cars | M12: 124 | N12: S18_1589 | O12: AV Stores, Co. | P12: (171) 555-1555 | Q12: Fauntleroy Circus | R12: N/A | S12: Manchester | T12: N/A | U12: EC2 5NT | V12: UK | W12: EMEA | X12: Ashworth | Y12: Victoria | Z12: Medium
A13: 10111 | B13: 33 | C13: 99.66 | D13: 6 | E13: 3288.78 | F13: 37705 | G13: =TEXT(F13,"MMM") -> Mar | H13: Shipped | I13: 1 | J13: 3 | K13: 2003 | L13: Vintage Cars | M13: 102 | N13: S18_1342 | O13: Mini Wheels Co. | P13: 6505555787 | Q13: 5557 North Pendale Street | R13: N/A | S13: San Francisco | T13: CA | U13: N/A | V13: USA | W13: NA | X13: Murphy | Y13: Julie | Z13: Medium
A14: 10112 | B14: 29 | C14: 100 | D14: 1 | E14: 7209.11 | F14: 37704 | G14: =TEXT(F14,"MMM") -> Mar | H14: Shipped | I14: 1 | J14: 3 | K14: 2003 | L14: Classic Cars | M14: 214 | N14: S10_1949 | O14: Volvo Model Replicas, Co | P14: 0921-12 3555 | Q14: Berguvsv„gen 8 | R14: N/A | S14: Lule | T14: N/A | U14: S-958 22 | V14: Sweden | W14: EMEA | X14: Berglund | Y14: Christina | Z14: Large
A15: 10113 | B15: 21 | C15: 100 | D15: 2 | E15: 3415.44 | F15: 37706 | G15: =TEXT(F15,"MMM") -> Mar | H15: Shipped | I15: 1 | J15: 3 | K15: 2003 | L15: Trucks and Buses | M15: 136 | N15: S12_1666 | O15: Mini Gifts Distributors Ltd. | P15: 4155551450 | Q15: 5677 Strong St. | R15: N/A | S15: San Rafael | T15: CA | U15: 97562 | V15: USA | W15: NA | X15: Nelson | Y15: Valarie | Z15: Medium
A16: 10114 | B16: 31 | C16: 100 | D16: 8 | E16: 4305.28 | F16: 37712 | G16: =TEXT(F16,"MMM") -> Apr | H16: Shipped | I16: 2 | J16: 4 | K16: 2003 | L16: Classic Cars | M16: 147 | N16: S10_4962 | O16: La Corne D'abondance, Co. | P16: (1) 42.34.2555 | Q16: 265, boulevard Charonne | R16: N/A | S16: Paris | T16: N/A | U16: 75012 | V16: France | W16: EMEA | X16: Bertrand | Y16: Marie | Z16: Medium
A17: 10115 | B17: 46 | C17: 100 | D17: 5 | E17: 5723.78 | F17: 37715 | G17: =TEXT(F17,"MMM") -> Apr | H17: Shipped | I17: 2 | J17: 4 | K17: 2003 | L17: Trucks and Buses | M17: 118 | N17: S12_4473 | O17: Classic Legends Inc. | P17: 2125558493 | Q17: 5905 Pompton St. | R17: Suite 750 | S17: NYC | T17: NY | U17: 10022 | V17: USA | W17: NA | X17: Hernandez | Y17: Maria | Z17: Medium
A18: 10116 | B18: 27 | C18: 63.38 | D18: 1 | E18: 1711.26 | F18: 37722 | G18: =TEXT(F18,"MMM") -> Apr | H18: Shipped | I18: 2 | J18: 4 | K18: 2003 | L18: Trains | M18: 62 | N18: S32_3207 | O18: Royale Belge | P18: (071) 23 67 2555 | Q18: Boulevard Tirou, 255 | R18: N/A | S18: Charleroi | T18: N/A | U18: B-6000 | V18: Belgium | W18: EMEA | X18: Cartrain | Y18: Pascale | Z18: Small
A19: 10117 | B19: 33 | C19: 100 | D19: 9 | E19: 6034.38 | F19: 37727 | G19: =TEXT(F19,"MMM") -> Apr | H19: Shipped | I19: 2 | J19: 4 | K19: 2003 | L19: Classic Cars | M19: 207 | N19: S12_1108 | O19: Dragon Souveniers, Ltd. | P19: +65 221 7555 | Q19: Bronz Sok., Bronz Apt. 3/6 Tesvikiye | R19: N/A | S19: Singapore | T19: N/A | U19: 79903 | V19: Singapore | W19: Japan | X19: Natividad | Y19: Eric | Z19: Medium
A20: 10118 | B20: 36 | C20: 100 | D20: 1 | E20: 4219.2 | F20: 37732 | G20: =TEXT(F20,"MMM") -> Apr | H20: Shipped | I20: 2 | J20: 4 | K20: 2003 | L20: Ships | M20: 100 | N20: S700_3505 | O20: Enaco Distributors | P20: (93) 203 4555 | Q20: Rambla de Catalu¤a, 23 | R20: N/A | S20: Barcelona | T20: N/A | U20: 8022 | V20: Spain | W20: EMEA | X20: Saavedra | Y20: Eduardo | Z20: Medium
A21: 10119 | B21: 46 | C21: 100 | D21: 11 | E21: 5004.8 | F21: 37739 | G21: =TEXT(F21,"MMM") -> Apr | H21: Shipped | I21: 2 | J21: 4 | K21: 2003 | L21: Classic Cars | M21: 136 | N21: S10_4757 | O21: Salzburg Collectables | P21: 6562-9555 | Q21: Geislweg 14 | R21: N/A | S21: Salzburg | T21: N/A | U21: 5020 | V21: Austria | W21: EMEA | X21: Pipps | Y21: Georg | Z21: Medium
A22: 10120 | B22: 29 | C22: 96.34 | D22: 3 | E22: 2793.86 | F22: 37740 | G22: =TEXT(F22,"MMM") -> Apr | H22: Shipped | I22: 2 | J22: 4 | K22: 2003 | L22: Motorcycles | M22: 118 | N22: S10_2016 | O22: Australian Collectors, Co. | P22: 03 9520 4555 | Q22: 636 St Kilda Road | R22: Level 3 | S22: Melbourne | T22: Victoria | U22: 3004 | V22: Australia | W22: APAC | X22: Ferguson | Y22: Peter | Z22: Small
A23: 10121 | B23: 34 | C23: 81.35 | D23: 5 | E23: 2765.9 | F23: 37748 | G23: =TEXT(F23,"MMM") -> May | H23: Shipped | I23: 2 | J23: 5 | K23: 2003 | L23: Motorcycles | M23: 95 | N23: S10_1678 | O23: Reims Collectables | P23: 26.47.1555 | Q23: 59 rue de l'Abbaye | R23: N/A | S23: Reims | T23: N/A | U23: 51100 | V23: France | W23: EMEA | X23: Henriot | Y23: Paul | Z23: Small
A24: 10122 | B24: 42 | C24: 100 | D24: 10 | E24: 7599.9 | F24: 37749 | G24: =TEXT(F24,"MMM") -> May | H24: Shipped | I24: 2 | J24: 5 | K24: 2003 | L24: Classic Cars | M24: 194 | N24: S12_1099 | O24: Marseille Mini Autos | P24: 91.24.4555 | Q24: 12, rue des Bouchers | R24: N/A | S24: Marseille | T24: N/A | U24: 13008 | V24: France | W24: EMEA | X24: Lebihan | Y24: Laurence | Z24: Large
A25: 10123 | B25: 26 | C25: 100 | D25: 2 | E25: 3073.72 | F25: 37761 | G25: =TEXT(F25,"MMM") -> May | H25: Shipped | I25: 2 | J25: 5 | K25: 2003 | L25: Classic Cars | M25: 124 | N25: S18_1589 | O25: Atelier graphique | P25: 40.32.2555 | Q25: 54, rue Royale | R25: N/A | S25: Nantes | T25: N/A | U25: 44000 | V25: France | W25: EMEA | X25: Schmitt | Y25: Carine | Z25: Medium
A26: 10124 | B26: 21 | C26: 100 | D26: 6 | E26: 2856 | F26: 37762 | G26: =TEXT(F26,"MMM") -> May | H26: Shipped | I26: 2 | J26: 5 | K26: 2003 | L26: Vintage Cars | M26: 170 | N26: S18_1749 | O26: Signal Gift Stores | P26: 7025551838 | Q26: 8489 Strong St. | R26: N/A | S26: Las Vegas | T26: NV | U26: 83030 | V26: USA | W26: NA | X26: King | Y26: Sue | Z26: Small
A27: 10125 | B27: 32 | C27: 100 | D27: 1 | E27: 3254.72 | F27: 37762 | G27: =TEXT(F27,"MMM") -> May | H27: Shipped | I27: 2 | J27: 5 | K27: 2003 | L27: Vintage Cars | M27: 102 | N27: S18_1342 | O27: Australian Collectors, Co. | P27: 03 9520 4555 | Q27: 636 St Kilda Road | R27: Level 3 | S27: Melbourne | T27: Victoria | U27: 3004 | V27: Australia | W27: APAC | X27: Ferguson | Y27: Peter | Z27: Medium
A28: 10126 | B28: 38 | C28: 100 | D28: 11 | E28: 7329.06 | F28: 37769 | G28: =TEXT(F28,"MMM") -> May | H28: Shipped | I28: 2 | J28: 5 | K28: 2003 | L28: Classic Cars | M28: 214 | N28: S10_1949 | O28: Corrida Auto Replicas, Ltd | P28: (91) 555 22 82 | Q28: C/ Araquil, 67 | R28: N/A | S28: Madrid | T28: N/A | U28: 28023 | V28: Spain | W28: EMEA | X28: Sommer | Y28: Mart¡n | Z28: Large
A29: 10127 | B29: 46 | C29: 100 | D29: 2 | E29: 11279.2 | F29: 37775 | G29: =TEXT(F29,"MMM") -> Jun | H29: Shipped | I29: 2 | J29: 6 | K29: 2003 | L29: Classic Cars | M29: 207 | N29: S12_1108 | O29: Muscle Machine Inc | P29: 2125557413 | Q29: 4092 Furth Circle | R29: Suite 400 | S29: NYC | T29: NY | U29: 10022 | V29: USA | W29: NA | X29: Young | Y29: Jeff | Z29: Large
A30: 10128 | B30: 41 | C30: 100 | D30: 2 | E30: 5544.02 | F30: 37778 | G30: =TEXT(F30,"MMM") -> Jun | H30: Shipped | I30: 2 | J30: 6 | K30: 2003 | L30: Vintage Cars | M30: 136 | N30: S18_3140 | O30: Euro Shopping Channel | P30: (91) 555 94 44 | Q30: C/ Moralzarzal, 86 | R30: N/A | S30: Madrid | T30: N/A | U30: 28034 | V30: Spain | W30: EMEA | X30: Freyre | Y30: Diego | Z30: Medium
A31: 10129 | B31: 33 | C31: 100 | D31: 2 | E31: 4398.24 | F31: 37784 | G31: =TEXT(F31,"MMM") -> Jun | H31: Shipped | I31: 2 | J31: 6 | K31: 2003 | L31: Classic Cars | M31: 136 | N31: S10_4757 | O31: Stylish Desk Decors, Co. | P31: (171) 555-0297 | Q31: 35 King George | R31: N/A | S31: London | T31: N/A | U31: WX3 6FW | V31: UK | W31: EMEA | X31: Brown | Y31: Ann | Z31: Medium
A32: 10130 | B32: 40 | C32: 96.34 | D32: 2 | E32: 3853.6 | F32: 37788 | G32: =TEXT(F32,"MMM") -> Jun | H32: Shipped | I32: 2 | J32: 6 | K32: 2003 | L32: Ships | M32: 86 | N32: S18_3029 | O32: Auto-Moto Classics Inc. | P32: 6175558428 | Q32: 16780 Pompton St. | R32: N/A | S32: Brickhaven | T32: MA | U32: 58339 | V32: USA | W32: NA | X32: Taylor | Y32: Leslie | Z32: Medium
A33: 10131 | B33: 21 | C33: 100 | D33: 4 | E33: 2781.66 | F33: 37788 | G33: =TEXT(F33,"MMM") -> Jun | H33: Shipped | I33: 2 | J33: 6 | K33: 2003 | L33: Planes | M33: 157 | N33: S18_1662 | O33: Gift Ideas Corp. | P33: 2035554407 | Q33: 2440 Pompton St. | R33: N/A | S33: Glendale | T33: CT | U33: 97561 | V33: USA | W33: NA | X33: Lewis | Y33: Dan | Z33: Small
A34: 10133 | B34: 49 | C34: 69.27 | D34: 3 | E34: 3394.23 | F34: 37799 | G34: =TEXT(F34,"MMM") -> Jun | H34: Shipped | I34: 2 | J34: 6 | K34: 2003 | L34: Planes | M34: 84 | N34: S18_2581 | O34: Euro Shopping Channel | P34: (91) 555 94 44 | Q34: C/ Moralzarzal, 86 | R34: N/A | S34: Madrid | T34: N/A | U34: 28034 | V34: Spain | W34: EMEA | X34: Freyre | Y34: Diego | Z34: Medium
A35: 10134 | B35: 41 | C35: 94.74 | D35: 2 | E35: 3884.34 | F35: 37803 | G35: =TEXT(F35,"MMM") -> Jul | H35: Shipped | I35: 3 | J35: 7 | K35: 2003 | L35: Motorcycles | M35: 95 | N35: S10_1678 | O35: Lyon Souveniers | P35: +33 1 46 62 7555 | Q35: 27 rue du Colonel Pierre Avia | R35: N/A | S35: Paris | T35: N/A | U35: 75508 | V35: France | W35: EMEA | X35: Da Cunha | Y35: Daniel | Z35: Medium
A36: 10135 | B36: 42 | C36: 100 | D36: 7 | E36: 8008.56 | F36: 37804 | G36: =TEXT(F36,"MMM") -> Jul | H36: Shipped | I36: 3 | J36: 7 | K36: 2003 | L36: Classic Cars | M36: 194 | N36: S12_1099 | O36: Mini Gifts Distributors Ltd. | P36: 4155551450 | Q36: 5677 Strong St. | R36: N/A | S36: San Rafael | T36: CA | U36: 97562 | V36: USA | W36: NA | X36: Nelson | Y36: Valarie | Z36: Large
A37: 10136 | B37: 25 | C37: 100 | D37: 2 | E37: 3644.75 | F37: 37806 | G37: =TEXT(F37,"MMM") -> Jul | H37: Shipped | I37: 3 | J37: 7 | K37: 2003 | L37: Classic Cars | M37: 141 | N37: S18_1129 | O37: Alpha Cognac | P37: 61.77.6555 | Q37: 1 rue Alsace-Lorraine | R37: N/A | S37: Toulouse | T37: N/A | U37: 31000 | V37: France | W37: EMEA | X37: Roulet | Y37: Annette | Z37: Medium
A38: 10137 | B38: 44 | C38: 99.55 | D38: 2 | E38: 4380.2 | F38: 37812 | G38: =TEXT(F38,"MMM") -> Jul | H38: Shipped | I38: 3 | J38: 7 | K38: 2003 | L38: Classic Cars | M38: 124 | N38: S18_1589 | O38: Reims Collectables | P38: 26.47.1555 | Q38: 59 rue de l'Abbaye | R38: N/A | S38: Reims | T38: N/A | U38: 51100 | V38: France | W38: EMEA | X38: Henriot | Y38: Paul | Z38: Medium
A39: 10139 | B39: 31 | C39: 100 | D39: 7 | E39: 3184.94 | F39: 37818 | G39: =TEXT(F39,"MMM") -> Jul | H39: Shipped | I39: 3 | J39: 7 | K39: 2003 | L39: Vintage Cars | M39: 102 | N39: S18_1342 | O39: Souveniers And Things Co. | P39: +61 2 9495 8555 | Q39: Monitor Money Building, 815 Pacific Hwy | R39: Level 6 | S39: Chatswood | T39: NSW | U39: 2067 | V39: Australia | W39: APAC | X39: Huxley | Y39: Adrian | Z39: Medium
A40: 10140 | B40: 37 | C40: 100 | D40: 11 | E40: 7374.1 | F40: 37826 | G40: =TEXT(F40,"MMM") -> Jul | H40: Shipped | I40: 3 | J40: 7 | K40: 2003 | L40: Classic Cars | M40: 214 | N40: S10_1949 | O40: Technics Stores Inc. | P40: 6505556809 | Q40: 9408 Furth Circle | R40: N/A | S40: Burlingame | T40: CA | U40: 94217 | V40: USA | W40: NA | X40: Hirano | Y40: Juri | Z40: Large
...

Sheet Data Transformation
A1: ORDERDATE | B1: Month | C1: Year | D1: Sale Categeory | E1: Order Sales
A2: 37676 | B2: =TEXT('sales_data_sample (2)'!F2,"MMM") -> Jan | C2: =YEAR(A2) -> 2003 | D2: =IF('sales_data_sample (2)'!E2>5000,"High Sales","Low Sales") -> High Sales | E2: =IF('sales_data_sample (2)'!C2>=50,"Bulk Order","Normal Order") -> Bulk Order
A3: 37748 | B3: =TEXT('sales_data_sample (2)'!F3,"MMM") -> Jan | C3: =YEAR(A3) -> 2003 | D3: =IF('sales_data_sample (2)'!E3>5000,"High Sales","Low Sales") -> Low Sales | E3: =IF('sales_data_sample (2)'!C3>=50,"Bulk Order","Normal Order") -> Bulk Order
A4: 37803 | B4: =TEXT('sales_data_sample (2)'!F4,"MMM") -> Jan | C4: =YEAR(A4) -> 2003 | D4: =IF('sales_data_sample (2)'!E4>5000,"High Sales","Low Sales") -> Low Sales | E4: =IF('sales_data_sample (2)'!C4>=50,"Bulk Order","Normal Order") -> Bulk Order
A5: 37858 | B5: =TEXT('sales_data_sample (2)'!F5,"MMM") -> Jan | C5: =YEAR(A5) -> 2003 | D5: =IF('sales_data_sample (2)'!E5>5000,"High Sales","Low Sales") -> High Sales | E5: =IF('sales_data_sample (2)'!C5>=50,"Bulk Order","Normal Order") -> Bulk Order
A6: 37904 | B6: =TEXT('sales_data_sample (2)'!F6,"MMM") -> Jan | C6: =YEAR(A6) -> 2003 | D6: =IF('sales_data_sample (2)'!E6>5000,"High Sales","Low Sales") -> High Sales | E6: =IF('sales_data_sample (2)'!C6>=50,"Bulk Order","Normal Order") -> Bulk Order
A7: 37922 | B7: =TEXT('sales_data_sample (2)'!F7,"MMM") -> Feb | C7: =YEAR(A7) -> 2003 | D7: =IF('sales_data_sample (2)'!E7>5000,"High Sales","Low Sales") -> High Sales | E7: =IF('sales_data_sample (2)'!C7>=50,"Bulk Order","Normal Order") -> Bulk Order
A8: 37936 | B8: =TEXT('sales_data_sample (2)'!F8,"MMM") -> Feb | C8: =YEAR(A8) -> 2003 | D8: =IF('sales_data_sample (2)'!E8>5000,"High Sales","Low Sales") -> High Sales | E8: =IF('sales_data_sample (2)'!C8>=50,"Bulk Order","Normal Order") -> Bulk Order
A9: 37943 | B9: =TEXT('sales_data_sample (2)'!F9,"MMM") -> Feb | C9: =YEAR(A9) -> 2003 | D9: =IF('sales_data_sample (2)'!E9>5000,"High Sales","Low Sales") -> Low Sales | E9: =IF('sales_data_sample (2)'!C9>=50,"Bulk Order","Normal Order") -> Bulk Order
A10: 37956 | B10: =TEXT('sales_data_sample (2)'!F10,"MMM") -> Mar | C10: =YEAR(A10) -> 2003 | D10: =IF('sales_data_sample (2)'!E10>5000,"High Sales","Low Sales") -> High Sales | E10: =IF('sales_data_sample (2)'!C10>=50,"Bulk Order","Normal Order") -> Bulk Order
A11: 38001 | B11: =TEXT('sales_data_sample (2)'!F11,"MMM") -> Mar | C11: =YEAR(A11) -> 2004 | D11: =IF('sales_data_sample (2)'!E11>5000,"High Sales","Low Sales") -> Low Sales | E11: =IF('sales_data_sample (2)'!C11>=50,"Bulk Order","Normal Order") -> Bulk Order
A12: 38037 | B12: =TEXT('sales_data_sample (2)'!F12,"MMM") -> Mar | C12: =YEAR(A12) -> 2004 | D12: =IF('sales_data_sample (2)'!E12>5000,"High Sales","Low Sales") -> High Sales | E12: =IF('sales_data_sample (2)'!C12>=50,"Bulk Order","Normal Order") -> Bulk Order
A13: 38082 | B13: =TEXT('sales_data_sample (2)'!F13,"MMM") -> Mar | C13: =YEAR(A13) -> 2004 | D13: =IF('sales_data_sample (2)'!E13>5000,"High Sales","Low Sales") -> Low Sales | E13: =IF('sales_data_sample (2)'!C13>=50,"Bulk Order","Normal Order") -> Bulk Order
... A308: 38240 | B308: =TEXT('sales_data_sample (2)'!F308,"MMM") -> May | C308: =YEAR(A308) -> 2004 | D308: =IF('sales_data_sample (2)'!E308>5000,"High Sales","Low Sales") -> High Sales | E308: =IF('sales_data_sample (2)'!C308>=50,"Bulk Order","Normal Order") -> Bulk Order

Sheet Analysis
A1: Avg Qty Order | D1: Total Qty Order
A2: {=_xlfn.UNIQUE('sales_data_sample (2)'!L2:L308)} -> Vintage Cars | B2: =AVERAGEIFS('sales_data_sample (2)'!B$2:B$308,'sales_data_sample (2)'!$L$2:$L$308,Analysis!A2) -> 34.5 | D2: {=_xlfn.UNIQUE('sales_data_sample (2)'!L2:L308)} -> Vintage Cars | E2: =SUMIFS('sales_data_sample (2)'!$B$2:$B$308,'sales_data_sample (2)'!$L$2:$L$308,Analysis!D2) -> 1932 | H2: Total Sales in Country Wise | P2: Total Sales | R2: Average Sales
A3: Classic Cars | B3: =AVERAGEIFS('sales_data_sample (2)'!B$2:B$308,'sales_data_sample (2)'!$L$2:$L$308,Analysis!A3) -> 35.072727 | D3: Classic Cars | E3: =SUMIFS('sales_data_sample (2)'!$B$2:$B$308,'sales_data_sample (2)'!$L$2:$L$308,Analysis!D3) -> 5787 | H3: {=_xlfn.UNIQUE('sales_data_sample (2)'!$V$2:$V$308)} -> USA | I3: =SUMIFS('sales_data_sample (2)'!$E$2:$E$308,'sales_data_sample (2)'!$V$2:$V$308,Analysis!H3) -> 524383.89 | P3: =SUM('sales_data_sample (2)'!$E$2:$E$308) -> 1408665.5 | R3: =AVERAGE('sales_data_sample (2)'!$E$2:$E$308) -> 4588.4869
A4: Planes | B4: =AVERAGEIFS('sales_data_sample (2)'!B$2:B$308,'sales_data_sample (2)'!$L$2:$L$308,Analysis!A4) -> 35.2 | D4: Planes | E4: =SUMIFS('sales_data_sample (2)'!$B$2:$B$308,'sales_data_sample (2)'!$L$2:$L$308,Analysis!D4) -> 704 | H4: Germany | I4: =SUMIFS('sales_data_sample (2)'!$E$2:$E$308,'sales_data_sample (2)'!$V$2:$V$308,Analysis!H4) -> 35784.47
A5: Motorcycles | B5: =AVERAGEIFS('sales_data_sample (2)'!B$2:B$308,'sales_data_sample (2)'!$L$2:$L$308,Analysis!A5) -> 36.565217 | D5: Motorcycles | E5: =SUMIFS('sales_data_sample (2)'!$B$2:$B$308,'sales_data_sample (2)'!$L$2:$L$308,Analysis!D5) -> 1682 | H5: Norway | I5: =SUMIFS('sales_data_sample (2)'!$E$2:$E$308,'sales_data_sample (2)'!$V$2:$V$308,Analysis!H5) -> 41482.37 | P5: Max Sales | R5: Min Sales
A6: Trucks and Buses | B6: =AVERAGEIFS('sales_data_sample (2)'!B$2:B$308,'sales_data_sample (2)'!$L$2:$L$308,Analysis!A6) -> 36 | D6: Trucks and Buses | E6: =SUMIFS('sales_data_sample (2)'!$B$2:$B$308,'sales_data_sample (2)'!$L$2:$L$308,Analysis!D6) -> 468 | H6: Spain | I6: =SUMIFS('sales_data_sample (2)'!$E$2:$E$308,'sales_data_sample (2)'!$V$2:$V$308,Analysis!H6) -> 157078.92 | P6: =MAX('sales_data_sample (2)'!$E$2:$E$308) -> 12001 | R6: =MIN('sales_data_sample (2)'!$E$2:$E$308) -> 553.95
A7: Trains | B7: =AVERAGEIFS('sales_data_sample (2)'!B$2:B$308,'sales_data_sample (2)'!$L$2:$L$308,Analysis!A7) -> 29.5 | D7: Trains | E7: =SUMIFS('sales_data_sample (2)'!$B$2:$B$308,'sales_data_sample (2)'!$L$2:$L$308,Analysis!D7) -> 59 | H7: Denmark | I7: =SUMIFS('sales_data_sample (2)'!$E$2:$E$308,'sales_data_sample (2)'!$V$2:$V$308,Analysis!H7) -> 39151.18
A8: Ships | B8: =AVERAGEIFS('sales_data_sample (2)'!B$2:B$308,'sales_data_sample (2)'!$L$2:$L$308,Analysis!A8) -> 35.2 | D8: Ships | E8: =SUMIFS('sales_data_sample (2)'!$B$2:$B$308,'sales_data_sample (2)'!$L$2:$L$308,Analysis!D8) -> 176 | H8: Italy | I8: =SUMIFS('sales_data_sample (2)'!$E$2:$E$308,'sales_data_sample (2)'!$V$2:$V$308,Analysis!H8) -> 51544.44
B9: =SUM(B2:B8) -> 242.03794 | E9: =SUM(E2:E8) -> 10808 | H9: Philippines | I9: =SUMIFS('sales_data_sample (2)'!$E$2:$E$308,'sales_data_sample (2)'!$V$2:$V$308,Analysis!H9) -> 17154.35
H10: UK | I10: =SUMIFS('sales_data_sample (2)'!$E$2:$E$308,'sales_data_sample (2)'!$V$2:$V$308,Analysis!H10) -> 58880.53
A11: Avg Sales | D11: Total Sales | H11: Sweden | I11: =SUMIFS('sales_data_sample (2)'!$E$2:$E$308,'sales_data_sample (2)'!$V$2:$V$308,Analysis!H11) -> 36716.41
A12: {=_xlfn.UNIQUE('sales_data_sample (2)'!L2:L308)} -> Vintage Cars | B12: =AVERAGEIFS('sales_data_sample (2)'!$E$2:$E$308,'sales_data_sample (2)'!$L$2:$L$308,Analysis!A12) -> 3738.2852 | D12: {=_xlfn.UNIQUE('sales_data_sample (2)'!L2:L308)} -> Vintage Cars | E12: =SUMIFS('sales_data_sample (2)'!$E$2:$E$308,'sales_data_sample (2)'!$L$2:$L$308,Analysis!D12) -> 209343.97 | H12: France | I12: =SUMIFS('sales_data_sample (2)'!$E$2:$E$308,'sales_data_sample (2)'!$V$2:$V$308,Analysis!H12) -> 161203.7
A13: Classic Cars | B13: =AVERAGEIFS('sales_data_sample (2)'!$E$2:$E$308,'sales_data_sample (2)'!$L$2:$L$308,Analysis!A13) -> 5229.557 | D13: Classic Cars | E13: =SUMIFS('sales_data_sample (2)'!$E$2:$E$308,'sales_data_sample (2)'!$L$2:$L$308,Analysis!D13) -> 862876.9 | H13: Belgium | I13: =SUMIFS('sales_data_sample (2)'!$E$2:$E$308,'sales_data_sample (2)'!$V$2:$V$308,Analysis!H13) -> 21988.67
A14: Planes | B14: =AVERAGEIFS('sales_data_sample (2)'!$E$2:$E$308,'sales_data_sample (2)'!$L$2:$L$308,Analysis!A14) -> 4378.907 | D14: Planes | E14: =SUMIFS('sales_data_sample (2)'!$E$2:$E$308,'sales_data_sample (2)'!$L$2:$L$308,Analysis!D14) -> 87578.14 | H14: Singapore | I14: =SUMIFS('sales_data_sample (2)'!$E$2:$E$308,'sales_data_sample (2)'!$V$2:$V$308,Analysis!H14) -> 47702.18
A15: Motorcycles | B15: =AVERAGEIFS('sales_data_sample (2)'!$E$2:$E$308,'sales_data_sample (2)'!$L$2:$L$308,Analysis!A15) -> 3681.3048 | D15: Motorcycles | E15: =SUMIFS('sales_data_sample (2)'!$E$2:$E$308,'sales_data_sample (2)'!$L$2:$L$308,Analysis!D15) -> 169340.02 | H15: Austria | I15: =SUMIFS('sales_data_sample (2)'!$E$2:$E$308,'sales_data_sample (2)'!$V$2:$V$308,Analysis!H15) -> 27942.6
A16: Trucks and Buses | B16: =AVERAGEIFS('sales_data_sample (2)'!$E$2:$E$308,'sales_data_sample (2)'!$L$2:$L$308,Analysis!A16) -> 4331.68 | D16: Trucks and Buses | E16: =SUMIFS('sales_data_sample (2)'!$E$2:$E$308,'sales_data_sample (2)'!$L$2:$L$308,Analysis!D16) -> 56311.84 | H16: Australia | I16: =SUMIFS('sales_data_sample (2)'!$E$2:$E$308,'sales_data_sample (2)'!$V$2:$V$308,Analysis!H16) -> 78724.68
A17: Trains | B17: =AVERAGEIFS('sales_data_sample (2)'!$E$2:$E$308,'sales_data_sample (2)'!$L$2:$L$308,Analysis!A17) -> 2759.47 | D17: Trains | E17: =SUMIFS('sales_data_sample (2)'!$E$2:$E$308,'sales_data_sample (2)'!$L$2:$L$308,Analysis!D17) -> 5518.94 | H17: Finland | I17: =SUMIFS('sales_data_sample (2)'!$E$2:$E$308,'sales_data_sample (2)'!$V$2:$V$308,Analysis!H17) -> 33648.3
A18: Ships | B18: =AVERAGEIFS('sales_data_sample (2)'!$E$2:$E$308,'sales_data_sample (2)'!$L$2:$L$308,Analysis!A18) -> 3539.134 | D18: Ships | E18: =SUMIFS('sales_data_sample (2)'!$E$2:$E$308,'sales_data_sample (2)'!$L$2:$L$308,Analysis!D18) -> 17695.67 | H18: Canada | I18: =SUMIFS('sales_data_sample (2)'!$E$2:$E$308,'sales_data_sample (2)'!$V$2:$V$308,Analysis!H18) -> 32586.08
B19: =SUM(B12:B18) -> 27658.338 | E19: =SUM(E12:E18) -> 1408665.5 | H19: Japan | I19: =SUMIFS('sales_data_sample (2)'!$E$2:$E$308,'sales_data_sample (2)'!$V$2:$V$308,Analysis!H19) -> 25491.37
H20: Ireland | I20: =SUMIFS('sales_data_sample (2)'!$E$2:$E$308,'sales_data_sample (2)'!$V$2:$V$308,Analysis!H20) -> 9251.19
H21: Switzerland | I21: =SUMIFS('sales_data_sample (2)'!$E$2:$E$308,'sales_data_sample (2)'!$V$2:$V$308,Analysis!H21) -> 7950.15 | L21: =AVERAGE(B12:B18) -> 3951.1911

Sheet Pivot Table
F2: Country | G2: Sum of SALES | I2: Product Line | J2: Sum of SALES
F3: Australia | G3: 78724.68 | I3: Classic Cars | J3: 862876.9
C4: QTR_ID | D4: Count of ORDERNUMBER | F4: Austria | G4: 27942.6 | I4: Motorcycles | J4: 169340.02
C5: Cancelled | D5: 4 | F5: Belgium | G5: 21988.67 | I5: Planes | J5: 87578.14
C6: Disputed | D6: 3 | F6: Canada | G6: 32586.08 | I6: Ships | J6: 17695.67
C7: In Process | D7: 6 | F7: Denmark | G7: 39151.18 | I7: Trains | J7: 5518.94
C8: On Hold | D8: 4 | F8: Finland | G8: 33648.3 | I8: Trucks and Buses | J8: 56311.84
C9: Resolved | D9: 4 | F9: France | G9: 161203.7 | I9: Vintage Cars | J9: 209343.97
C10: Shipped | D10: 286 | F10: Germany | G10: 35784.47 | I10: (blank)
C11: Grand Total | D11: 307 | F11: Ireland | G11: 9251.19 | I11: Grand Total | J11: 1408665.5
F12: Italy | G12: 51544.44
C13: Month | D13: Sum of SALES | F13: Japan | G13: 25491.37 | I13: Sum of SALES | J13: Column Labels
C14: Jan | D14: 109979.69 | F14: Norway | G14: 41482.37 | I14: QTR_ID | J14: 2003 | K14: 2004 | L14: 2005 | M14: Grand Total
C15: Feb | D15: 114294.27 | F15: Philippines | G15: 17154.35 | I15: 1 | J15: 69453.57 | K15: 134743.13 | L15: 126659.16 | M15: 330855.86
C16: Mar | D16: 106581.9 | F16: Singapore | G16: 47702.18 | I16: 2 | J16: 87922.81 | K16: 121869.99 | L16: 122874.4 | M16: 332667.2
C17: Apr | D17: 112145.03 | F17: Spain | G17: 157078.92 | I17: 3 | J17: 96382.03 | K17: 155497.07 | M17: 251879.1
C18: May | D18: 146003.9 | F18: Sweden | G18: 36716.41 | I18: 4 | J18: 250530.6 | K18: 242732.72 | M18: 493263.32
C19: Jun | D19: 74518.27 | F19: Switzerland | G19: 7950.15 | I19: Grand Total | J19: 504289.01 | K19: 654842.91 | L19: 249533.56 | M19: 1408665.5
C20: Jul | D20: 76429.62 | F20: UK | G20: 58880.53
C21: Aug | D21: 80698.98 | F21: USA | G21: 524383.89
C22: Sep | D22: 94750.5 | F22: (blank)
C23: Oct | D23: 156925.07 | F23: Grand Total | G23: 1408665.5
C24: Nov | D24: 270092.26
C25: Dec | D25: 66245.99
C26: (blank)
C27: Grand Total | D27: 1408665.5

Sheet Dashboard
A1: Sales Analysis Dasboard
